Workbook

Sheet Read Me
A1: Meta Builder: how every stat and talent is calculated
A3: Version | B3: v0.25 (pre-release). Built from the app's own code and data, so the numbers match what the planner uses.
A4: Game data | B4: deepwoken.co (talents, mantras, weapons, equipment, oaths, reference builds; October 2026). Traits: deepwoken.fandom.com/wiki/Traits.
A6: Sheet | B6: What it has
A7: Calculator | B7: Type stats in the yellow cells (blue text) and every result recalculates: Power, points left, talent cap, health and effective health, weapon damage, mantra damage, trait effects.
A8: Formulas | B8: Every calculation the app does, in plain words and as a formula, with where it lives in the code (src/template.html).
A9: Talents | B9: All 622 talents: requirements, cheapest way to meet them, whether they can be taken before the shrine, popularity, take rate given stats, damage/PEN bonus, synergies, exclusives, description.
A10: Mantras | B10: All 230 mantras: attunement, category, requirement, stat scaling, damage at levels 1-5, and live damage with the Calculator stats.
A11: Weapons | B11: All 231 weapons: type, requirement, base damage, PEN, stat scaling, and live hit damage with the Calculator stats.
A12: Outfits | B12: All outfits: physical/elemental armor, durability, requirement, talents they give.
A13: Equipment | B13: All equipment pieces: slot, health/armor, pip slots, requirement, set, talents they give.
A14: Enchants | B14: Weapon enchants and how each is counted.
A15: Oaths | B15: Each oath's stat requirement options and notes.
... A20: Codes | B20: STR Strength, FTD Fortitude, AGL Agility, INT Intelligence, WLL Willpower, CHA Charisma, HVY/MED/LHT Heavy/Medium/Light weapon, FLM Flamecharm, ICE Frostdraw, LTN Thundercall, WND Galebreathe, SDW Shadowcast, IRN Ironsing, BLD Bloodrend, MND = highest of INT/WLL/CHA, BOD = highest of STR/FTD/AGL, PWR = Power.

Sheet Calculator
A1: Calculator
A2: Change the yellow cells. Green cells are formulas. Take the "Before shrine", "Shrine leaves" and "Final" numbers from the app's stats table (Stats tab).
A4: Stats
A5: Code | B5: Stat | C5: Before shrine | D5: Shrine leaves | E5: Final | F5: Added after shrine
A6: STR | B6: Strength | C6: 1 | D6: 22 | E6: 22 | F6: =MAX(0,E6-D6) -> 0
A7: FTD | B7: Fortitude | C7: 50 | D7: 25 | E7: 25 | F7: =MAX(0,E7-D7) -> 0
A8: AGL | B8: Agility | C8: 40 | D8: 22 | E8: 22 | F8: =MAX(0,E8-D8) -> 0
A9: INT | B9: Intelligence | C9: 0 | D9: 0 | E9: 0 | F9: =MAX(0,E9-D9) -> 0
A10: WLL | B10: Willpower | C10: 40 | D10: 22 | E10: 22 | F10: =MAX(0,E10-D10) -> 0
A11: CHA | B11: Charisma | C11: 1 | D11: 22 | E11: 25 | F11: =MAX(0,E11-D11) -> 3
A12: HVY | B12: Heavy weapon | C12: 0 | D12: 0 | E12: 0 | F12: =MAX(0,E12-D12) -> 0
A13: MED | B13: Medium weapon | C13: 1 | D13: 22 | E13: 92 | F13: =MAX(0,E13-D13) -> 70
A14: LHT | B14: Light weapon | C14: 0 | D14: 0 | E14: 0 | F14: =MAX(0,E14-D14) -> 0
A15: FLM | B15: Flamecharm | C15: 0 | D15: 0 | E15: 0 | F15: =MAX(0,E15-D15) -> 0
A16: ICE | B16: Frostdraw | C16: 0 | D16: 0 | E16: 0 | F16: =MAX(0,E16-D16) -> 0
A17: LTN | B17: Thundercall | C17: 50 | D17: 22 | E17: 22 | F17: =MAX(0,E17-D17) -> 0
... A21: BLD | B21: Bloodrend | C21: 0 | D21: 0 | E21: 0 | F21: =MAX(0,E21-D21) -> 0
A22: MND | B22: Mind (highest of INT/WLL/CHA) | E22: =MAX(E9,E10,E11) -> 25
A23: BOD | B23: Body (highest of STR/FTD/AGL) | E23: =MAX(E6,E7,E8) -> 25
A24: Example values are the Iron Samurai example build.
A25: Traits (separate 12-point pool, max 6 each)
A26: Vitality | C26: 4 | D26: +10 health per point
A27: Proficiency | C27: 4 | D27: weapon scaling x(1+6.5%/pt), +2.5% weapon PEN/pt
A28: Songchant | C28: 4 | D28: mantra scaling x(1+6.5%/pt), +2.5% mantra PEN/pt
A29: Erudition | C29: 0 | D29: +30 ether, +5 tempo, +5% tempo gain per point
A30: Trait points left | C30: =Constants!$B$18-SUM(C26:C29) -> 0 | D30: must not go below 0; each trait at most 6
A32: Weapon and damage bonuses
A33: Weapon (name from the Weapons sheet) | C33: Shattered Katana | D33: pick any name in the Weapons sheet
A34: Base damage | C34: =INDEX(Weapons!$D$2:$D$232,MATCH(C33,Weapons!$A$2:$A$232,0)) -> 20
A35: Weapon PEN | C35: =INDEX(Weapons!$E$2:$E$232,MATCH(C33,Weapons!$A$2:$A$232,0)) -> 0.3
A36: Extra PEN from talents | C36: 0 | D36: sum of talent PEN (Talents sheet, PEN column)
A37: Unique damage bonus (not capped) | C37: 0 | D37: talents marked unique add outside the cap
A38: Talent damage bonus (raw sum) | C38: 0.3 | D38: sum of the Damage column of your talents
A39: Enchant hit multiplier | C39: 1 | D39: Enchants sheet: e.g. Deferred 1.07
A40: Enchant PEN | C40: 0 | D40: Enchants sheet: e.g. Sear 0.05
A41: Soulbreaker oath? (1 = yes) | C41: 0 | D41: adds +2.5% damage bonus
A42: PEN cap removed by a talent? (1 = yes) | C42: 0 | D42: some talents lift the 50% cap
A43: Talent damage bonus incl. oath | C43: =C38+Constants!$B$17*C41 -> 0.3
A44: PEN cap | C44: =IF(C42=1,1,Constants!$B$15) -> 0.5
A45: Damage bonus after soft cap | C45: =IF(C43>Constants!$B$13,MIN(Constants!$B$14,Constants!$B$13+(C43-Constants!$B$13)/2),C43) -> 0.275 | D45: full to +25%, half past it, max +50%
...

Sheet Formulas
A1: Area | B1: What | C1: How it is calculated | D1: Formula | E1: In the code
A2: Points | B2: Stat budget | C2: A Power 20 character has 330 points. Points used = points before the shrine - shrine refund + points added after - free attunement points - Shrine of Mastery refunds. | D2: used = preSum - refund + postSum - max(0, attunements-1) - mastery | E2: evaluate()
A3: Points | B3: Power | C3: Power from points invested. | D3: Power = clamp(floor((points - 15) / 15), 0, 20) | E3: powerAt()
A4: Points | B4: Next Power | C4: Points still needed for the next Power level. | D4: 15 x (Power + 2) - points used | E4: renderFinal()
A5: Points | B5: Free attunement points | C5: Every attunement after the first gets its first point free. | D5: discount = max(0, number of attunements above 0 - 1) | E5: evaluate()
A6: Shrine of Order | B6: When it can be used | C6: Only at Power 8 or higher (135 points invested before it). Below that the plan skips the shrine and the stats carry straight through. | D6: allowed = Power(preSum) >= 8 | E6: evaluate(), SHRINE_PWR
A7: Shrine of Order | B7: Averaging (deepwoken.co algorithm) | C7: Every stat above 0 is set to the average of the invested stats. No attribute may end more than 25 below its pre-shrine value: those are pinned at pre - 25 and the difference is taken evenly from the others (repeat until stable; attunements are exempt). Then values are rounded down, and leftover whole points are handed out one each to the unpinned stats while none would pass 100. Anything left is refunded. | D7: avg = sum/count; pinned k: pre_k - 25; others share the rest; floor; distribute remainder; refund = what is left | E7: shrine()
A8: Shrine of Order | B8: Pre-shrine is the peak | C8: An attribute (STR..CHA) raised above 1 before the shrine gets no points after it: either about 1 before and the rest after, or high before and the shrine brings it down. Weapon and attunement stats may be raised again (top builds do Ironsing 60 -> 80). Breaking it costs 20 points per point in the optimizer score. | D8: penalty = 20 x sum of points added after the shrine to attributes that were > 1 before | E8: evaluate() reup
A9: Shrine of Mastery | B9: Refunds | C9: Up to 3 points come off before (pre) or after (post) the Order shrine and are refunded; talents already taken stay. | D9: used -= mastery points | E9: evaluate(), masteryOf()
A10: Requirements | B10: Talent requirement options | C10: A talent can need stats (min values), "one of" groups (each option merged into the minimums, up to 16 options), combined sums (e.g. 75 combined weapon), prerequisite talents and mantras. Body = highest of STR/FTD/AGL, Mind = highest of INT/WLL/CHA, any weapon / any attunement expand into one option per stat. | D10: alternatives = expand(stats) x expand(one-of groups); each alternative = {min:{stat:value}, sum:[[stats],value]} | E10: reqAlts(), expandStats()
A11: Requirements | B11: Prerequisite chains | C11: A talent's requirement includes the stat needs of every prerequisite talent before it (merged as the highest of each stat). | D11: chain(t) = merge(req(t), chain(each prerequisite)) | E11: chainAlts(), chainStatic()
A12: Requirements | B12: Cost to meet | C12: Points needed to meet an alternative from given stats: the sum of what each minimum is short, plus what each combined sum is short. The cheapest alternative counts. | D12: cost = sum max(0, min_k - stat_k) + sum max(0, sumValue - sum of its stats); bestCost = min over alternatives | E12: altCost(), bestCost()
... A46: Import | B46: deepwoken.co | C46: deepwoken.co blocks other sites from reading its builds. The bookmark runs on the build page, reads the build there and opens Meta Builder with it in the address (#dwco=...), which imports on load. | D46: n/a | E46: DWCO_SNIP, dwbFromCoJson()

Sheet Talents
A1: Talent | B1: Category | C1: Rarity | D1: Pickable | E1: Requirement | F1: Cheapest way to meet it (with prerequisites) | G1: Points needed from 0 | H1: Can be taken before the shrine | I1: Popularity (% of top builds) | J1: Builds that can take it | K1: Builds that take it | L1: Take rate given stats | M1: Damage bonus | N1: PEN bonus | O1: Unique bonus | P1: Synergies (weight) | Q1: Exclusive with | R1: Description
A2: A World Without Song | B2: Silencer | C2: Advanced | D2: yes | E2: WND 75 · after Silencer's Blade · with prerequisites: WND 75 (Silencer's Blade) | F2: WND 75 | G2: 75 | H2: yes | I2: 0.11 | J2: 51 | K2: 43 | L2: =IF(J2>=5,K2/J2,"too few builds") -> 0.84313725 | M2: 0 | N2: 0 | R2: Every 3 hits with a Wind Mantra now procs Suffocating.
A3: Absolute Pitch | B3: Songmaster | C3: Advanced | D3: yes | E3: INT 100 | F3: INT 100 | G3: 100 | H3: yes | I3: 0.04 | J3: 32 | K3: 26 | L3: =IF(J3>=5,K3/J3,"too few builds") -> 0.8125 | M3: 0 | N3: 0 | R3: You can cast Ritual Mantras instantly.
A4: Absolute Radiance | B4: Dawnwalker | C4: Oath | D4: no | E4: after Oath: Dawnwalker | F4: none | G4: 0 | H4: no | I4: 0 | J4: 28 | K4: 12 | L4: =IF(J4>=5,K4/J4,"too few builds") -> 0.42857143 | M4: 0 | N4: 0 | R4: Dealing damage with Dawnwalker mantras briefly makes you immune to all elemental effects for a short period.
A5: Acceleration Points | B5: Jetstriker | C5: Oath | D5: no | E5: after Oath: Jetstriker | F5: none | G5: 0 | H5: no | I5: 0 | J5: 51 | K5: 20 | L5: =IF(J5>=5,K5/J5,"too few builds") -> 0.39215686 | M5: 0 | N5: 0 | R5: Striking an opponent in the back with mobility mantras or Basic Attacks now steals and grants additional momentum.
A6: Action Surge | B6: Vigil Swordsman | C6: Common | D6: yes | E6: AGL 70 | F6: AGL 70 | G6: 70 | H6: yes | I6: 0.07 | J6: 44 | K6: 23 | L6: =IF(J6>=5,K6/J6,"too few builds") -> 0.52272727 | M6: 0 | N6: 0 | R6: Adrenaline Surge now increases your swing speed by 0.04 for its duration.
A7: Adept Bloodrender | B7: Bloodrender | C7: Common | D7: no | E7: BLD 20 · after Bloodrender · with prerequisites: BLD 20 (Bloodrender) | F7: BLD 20 | G7: 20 | H7: yes | I7: 0.15 | J7: 88 | K7: 77 | L7: =IF(J7>=5,K7/J7,"too few builds") -> 0.875 | M7: 0 | N7: 0 | R7: You can now obtain 1-star Bloodrender mantras.
A8: Adept Flamecharmer | B8: Flamecharmer | C8: Common | D8: no | E8: FLM 20 · after Flamecharmer · with prerequisites: FLM 20 (Flamecharmer) | F8: FLM 20 | G8: 20 | H8: yes | I8: 0.17 | J8: 160 | K8: 81 | L8: =IF(J8>=5,K8/J8,"too few builds") -> 0.50625 | M8: 0 | N8: 0 | R8: You can now obtain 1-Star Leveled Flamecharmer Mantras.
A9: Adept Frostdrawer | B9: Frostdrawer | C9: Common | D9: no | E9: ICE 20 · after Frostdrawer · with prerequisites: ICE 20 (Frostdrawer) | F9: ICE 20 | G9: 20 | H9: yes | I9: 0.16 | J9: 112 | K9: 69 | L9: =IF(J9>=5,K9/J9,"too few builds") -> 0.61607143 | M9: 0 | N9: 0 | R9: You can now obtain 1-Star Leveled Frostdrawer Mantras.
A10: Adept Galebreather | B10: Galebreather | C10: Common | D10: no | E10: WND 20 · after Galebreather · with prerequisites: WND 20 (Galebreather) | F10: WND 20 | G10: 20 | H10: yes | I10: 0.13 | J10: 108 | K10: 49 | L10: =IF(J10>=5,K10/J10,"too few builds") -> 0.4537037 | M10: 0 | N10: 0 | R10: You can now obtain 1-Star Leveled Galebreathe mantras.
A11: Adept Ironsinger | B11: Ironsinger | C11: Common | D11: no | E11: IRN 20 · after Ironsinger · with prerequisites: IRN 20 (Ironsinger) | F11: IRN 20 | G11: 20 | H11: yes | I11: 0.14 | J11: 80 | K11: 69 | L11: =IF(J11>=5,K11/J11,"too few builds") -> 0.8625 | M11: 0 | N11: 0 | R11: You can now obtain 1-star Ironsinger mantras.
A12: Adept Shadowcaster | B12: Shadowcaster | C12: Common | D12: no | E12: SDW 20 · after Shadowcaster · with prerequisites: SDW 20 (Shadowcaster) | F12: SDW 20 | G12: 20 | H12: yes | I12: 0.1 | J12: 121 | K12: 50 | L12: =IF(J12>=5,K12/J12,"too few builds") -> 0.41322314 | M12: 0 | N12: 0 | R12: You can now obtain 1-star Leveled Shadowcaster Mantras.
A13: Adept Thundercaller | B13: Thundercaller | C13: Common | D13: no | E13: LTN 20 · after Thundercaller · with prerequisites: LTN 20 (Thundercaller) | F13: LTN 20 | G13: 20 | H13: yes | I13: 0.1 | J13: 106 | K13: 48 | L13: =IF(J13>=5,K13/J13,"too few builds") -> 0.45283019 | M13: 0 | N13: 0 | R13: You can now obtain 1-star Thundercaller mantras.
A14: Aerogliding | B14: Aeromancer | C14: Rare | D14: yes | E14: WND 35 · AGL 30 | F14: WND 35 · AGL 30 | G14: 65 | H14: yes | I14: 0.03 | J14: 54 | K14: 14 | L14: =IF(J14>=5,K14/J14,"too few builds") -> 0.25925926 | M14: 0 | N14: 0 | R14: When falling from a high place, hold space to generate wind currents until you land. More airtime with Gliders.
A15: After Cut | B15: Galeforce | C15: Common | D15: yes | E15: WND 40 | F15: WND 40 | G15: 40 | H15: yes | I15: 0.19 | J15: 100 | K15: 83 | L15: =IF(J15>=5,K15/J15,"too few builds") -> 0.83 | M15: 0.1 | N15: 0 | O15: yes | P15: Inhale (2) | R15: If an attack is physical and wind it will apply an after cut that does 5% of the damage you dealt. If an attack was a…
A16: Against All Odds | B16: Absolute Focus | C16: Common | D16: yes | E16: WLL 65 | F16: WLL 65 | G16: 65 | H16: yes | I16: 0.19 | J16: 125 | K16: 99 | L16: =IF(J16>=5,K16/J16,"too few builds") -> 0.792 | M16: 0 | N16: 0 | R16: For each combat tag you have on your character, increase your damage by 2% (max of 14%).
A17: Agility Unbounded | B17: Boundless Potential | C17: Common | D17: no | E17: AGL 75 | F17: AGL 75 | G17: 75 | H17: yes | I17: 0 | J17: 44 | K17: 12 | L17: =IF(J17>=5,K17/J17,"too few builds") -> 0.27272727 | M17: 0 | N17: 0 | R17: You have gained the ability to surpass your limits and train your agility to its fullest.
A18: Agitating Spark | B18: Immolator | C18: Common | D18: yes | E18: FLM 40 | F18: FLM 40 | G18: 40 | H18: yes | I18: 0.23 | J18: 130 | K18: 114 | L18: =IF(J18>=5,K18/J18,"too few builds") -> 0.87692308 | M18: 0 | N18: 0 | P18: Eruption Path: Lava Serpent (2) | R18: Applying Burning to enemies spreads it to anyone nearby. Including yourself.
A19: Air Pressure | B19: Legion Shock Trooper | C19: Common | D19: yes | E19: AGL 20 · WND 50 | F19: AGL 20 · WND 50 | G19: 70 | H19: yes | I19: 0.13 | J19: 71 | K19: 53 | L19: =IF(J19>=5,K19/J19,"too few builds") -> 0.74647887 | M19: 0 | N19: 0 | R19: Dodging an attack or hitting an enemy's block will transform your next dash into a Gale Dash. Gale Dashes carry you…
A20: All Above, Gods Below | B20: Heretic | C20: Advanced | D20: yes | E20: WLL 100 · INT 100 · after All the Dead Gods · with prerequisites: WLL 100 · INT 100 (All the Dead Gods) | F20: WLL 100 · INT 100 | G20: 200 | H20: yes | I20: 0 | J20: 9 | K20: 7 | L20: =IF(J20>=5,K20/J20,"too few builds") -> 0.77777778 | M20: 0 | N20: 0 | R20: Any healing your opponent were to receive while All The Dead Gods is active on them is stolen and given to you,…
A21: All Knowing | B21: Omniscient | C21: Rare | D21: yes | E21: INT 60 · mantra Prediction · with prerequisites: INT 60 (Prediction) | F21: INT 60 | G21: 60 | H21: yes | I21: 0.05 | J21: 77 | K21: 25 | L21: =IF(J21>=5,K21/J21,"too few builds") -> 0.32467532 | M21: 0 | N21: 0 | R21: Your prediction now ignores the range requirement to reflect attacks.
A22: All the Dead Gods | B22: Heretic | C22: Rare | D22: yes | E22: WLL 65 · INT 40 | F22: WLL 65 · INT 40 | G22: 105 | H22: yes | I22: 0.12 | J22: 73 | K22: 64 | L22: =IF(J22>=5,K22/J22,"too few builds") -> 0.87671233 | M22: 0 | N22: 0 | R22: Your Basic Attacks now apply anti-heal and 5% Heal Boost against PvE for 8s.
A23: All-Seeing Eye | B23: Blindseer | C23: Oath | D23: no | E23: after Oath: Blindseer | F23: none | G23: 0 | H23: no | I23: 0 | J23: 19 | K23: 3 | L23: =IF(J23>=5,K23/J23,"too few builds") -> 0.15789474 | M23: 0 | N23: 0 | R23: The mystic eye through which you now see the world can perceive the imperceptible. Invisible foes are highlighted.
A24: Alloyblood | B24: Ironsinger | C24: Advanced | D24: yes | E24: IRN 100 | F24: IRN 100 | G24: 100 | H24: yes | I24: 0.03 | J24: 17 | K24: 16 | L24: =IF(J24>=5,K24/J24,"too few builds") -> 0.94117647 | M24: 0 | N24: 0 | P24: Cauterized Wounds (2) | R24: You don't bleed like others do. Bleed damage reduced by 30%. Blood loss is reduced by 75%.
A25: Amplified Rage | B25: Jumpstarter | C25: Common | D25: yes | E25: LTN 35 · after Electrify · with prerequisites: LTN 35 (Electrify) | F25: LTN 35 | G25: 35 | H25: yes | I25: 0.09 | J25: 85 | K25: 40 | L25: =IF(J25>=5,K25/J25,"too few builds") -> 0.47058824 | M25: 0.1 | N25: 0 | Q25: Amplified Reflexes | R25: Amped now grants you an additional +10% weapon damage. Also self-damage and cooldown by 3x.
A26: Amplified Reflexes | B26: Jumpstarter | C26: Common | D26: yes | E26: LTN 35 · after Electrify · with prerequisites: LTN 35 (Electrify) | F26: LTN 35 | G26: 35 | H26: yes | I26: 0 | J26: 85 | K26: 9 | L26: =IF(J26>=5,K26/J26,"too few builds") -> 0.10588235 | M26: 0 | N26: 0 | Q26: Amplified Rage | R26: Amped now grants enhanced speed and parkour.
A27: An Ironsinger's Instinct | B27: Adaptive Arsenal | C27: Rare | D27: yes | E27: IRN 75 | F27: IRN 75 | G27: 75 | H27: yes | I27: 0.12 | J27: 66 | K27: 62 | L27: =IF(J27>=5,K27/J27,"too few builds") -> 0.93939394 | M27: 0 | N27: 0 | R27: Successfully dodging an attack coats you in metal and reduces the damage of the next attack taken.
A28: Anchor Shock | B28: Blightsurger | C28: Oath | D28: no | E28: after Oath: Blightsurger | F28: none | G28: 0 | H28: no | I28: 0 | J28: 11 | K28: 5 | L28: =IF(J28>=5,K28/J28,"too few builds") -> 0.45454545 | M28: 0 | N28: 0 | R28: Your Blightshock prevents targets from using mobility mantras.
A29: Ankle Cutter | B29: Silentheart | C29: Oath | D29: no | E29: after Oath: Silentheart | F29: none | G29: 0 | H29: no | I29: 0 | J29: 51 | K29: 20 | L29: =IF(J29>=5,K29/J29,"too few builds") -> 0.39215686 | M29: 0 | N29: 0
A30: Another Man's Trash | B30: Thief | C30: Advanced | D30: yes | E30: CHA 35 · AGL 10 · after Cap Artist, Pickpocket · with prerequisites: CHA 35 · AGL 25 (Cap Artist, Pickpocket) | F30: CHA 35 · AGL 25 | G30: 60 | H30: yes | I30: 0.04 | J30: 175 | K30: 20 | L30: =IF(J30>=5,K30/J30,"too few builds") -> 0.11428571 | M30: 0 | N30: 0
A31: Antithetic Salts | B31: Saltchemist | C31: Oath | D31: no | E31: after Oath: Saltchemist | F31: none | G31: 0 | H31: no | I31: 0 | J31: 18 | K31: 10 | L31: =IF(J31>=5,K31/J31,"too few builds") -> 0.55555556 | M31: 0 | N31: 0 | R31: Alter your brews to invert their effects. Does not count towards the ingredient limit.
A32: Apothecary | B32: Alchemist | C32: Common | D32: yes | E32: INT 10 | F32: INT 10 | G32: 10 | H32: yes | I32: 0.04 | J32: 329 | K32: 24 | L32: =IF(J32>=5,K32/J32,"too few builds") -> 0.072948328 | M32: 0 | N32: 0 | R32: Potions you prepare will have amplified positive effects when consumed, and amplified negative effects when thrown.
A33: Apparitions | B33: Specter | C33: Common | D33: yes | E33: WND 50 · after Haunted Path: Specter · with prerequisites: WND 50 (Haunted Path: Specter, Haunted Gale) | F33: WND 50 | G33: 50 | H33: yes | I33: 0.06 | J33: 90 | K33: 30 | L33: =IF(J33>=5,K33/J33,"too few builds") -> 0.33333333 | M33: 0 | N33: 0 | P33: Freezing Wight (2), Pressure Detonation (2), Haunted Gale (2), Phantom Step (2)
A34: Approaching Singularity | B34: All-Knowing | C34: Common | D34: yes | E34: INT 80 | F34: INT 80 | G34: 80 | H34: yes | I34: 0.11 | J34: 65 | K34: 59 | L34: =IF(J34>=5,K34/J34,"too few builds") -> 0.90769231 | M34: 0 | N34: 0 | R34: You now gain +1% Mantra PEN for every 10 point of Intelligence.
A35: Arc Module: Dash | B35: Arcwarder | C35: Oath | D35: no | E35: after Oath: Arcwarder | F35: none | G35: 0 | H35: no | I35: 0 | J35: 3 | K35: 1 | L35: =IF(J35>=5,K35/J35,"too few builds") -> too few builds | M35: 0 | N35: 0 | R35: [In Arc Suit] Your dashes become Jet Dashes, allowing you to attack while dashing.
A36: Arc Module: Eject | B36: Arcwarder | C36: Oath | D36: no | E36: after Oath: Arcwarder | F36: none | G36: 0 | H36: no | I36: 0 | J36: 3 | K36: 1 | L36: =IF(J36>=5,K36/J36,"too few builds") -> too few builds | M36: 0 | N36: 0 | R36: [In Arc Suit] When blockbroken, eject from your suit.
A37: Arc Module: Enhance | B37: Arcwarder | C37: Oath | D37: no | E37: after Oath: Arcwarder | F37: none | G37: 0 | H37: no | I37: 0 | J37: 3 | K37: 1 | L37: =IF(J37>=5,K37/J37,"too few builds") -> too few builds | M37: 0 | N37: 0 | R37: [In Arc Suit] Your Arcwarder Mantras deal increased damage.
A38: Arc Module: Guard | B38: Arcwarder | C38: Oath | D38: no | E38: after Oath: Arcwarder | F38: none | G38: 0 | H38: no | I38: 0 | J38: 3 | K38: 1 | L38: =IF(J38>=5,K38/J38,"too few builds") -> too few builds | M38: 0 | N38: 0 | R38: [In Arc Suit] You can block attacks from any direction and cannot be backstabbed.
A39: Arc Module: Leap | B39: Arcwarder | C39: Oath | D39: no | E39: after Oath: Arcwarder | F39: none | G39: 0 | H39: no | I39: 0 | J39: 3 | K39: 1 | L39: =IF(J39>=5,K39/J39,"too few builds") -> too few builds | M39: 0 | N39: 0 | R39: [In Arc Suit] Holding Spacebar after double jumping propels you up for a short duration.
A40: Arc Module: Null | B40: Arcwarder | C40: Oath | D40: no | E40: after Oath: Arcwarder | F40: none | G40: 0 | H40: no | I40: 0 | J40: 3 | K40: 1 | L40: =IF(J40>=5,K40/J40,"too few builds") -> too few builds | M40: 0 | N40: 0 | R40: [In Arc Suit] Outgoing and incoming enchant effects are nullified. Can be toggled with N.
...

Sheet Mantras
A1: Mantra | B1: Attunement | C1: Category | D1: Type | E1: Requirement | F1: Scale stat 1 | G1: Coef 1 | H1: Scale stat 2 | I1: Coef 2 | J1: Lv1 | K1: Lv2 | L1: Lv3 | M1: Lv4 | N1: Lv5 | O1: Level with Calculator stats | P1: Hit with Calculator stats
A2: Abyssal Ridge | B2: Monster | C2: Combat | D2: M | E2: no stat requirement | G2: 0 | I2: 0
A3: Abyssal Tendrils | B3: Monster | C3: Combat | D3: M | E3: no stat requirement | G3: 0 | I3: 0
A4: Adrenaline Surge | B4: AGL | C4: Support | D4: N | E4: AGL 20 | G4: 0 | I4: 0
A5: Agile Dash | B5: AGL | C5: Mobility | D5: N | E5: AGL 40 | G5: 0 | I5: 0
A6: Air Force | B6: WND | C6: Combat | D6: N | E6: WND 1 | F6: WND | G6: 2.75 | I6: 0 | J6: 22 | K6: 24.4 | L6: 26.8 | M6: 29.2 | N6: 31.6 | O6: =MAX(1,MIN(5,1+INT(IFERROR(INDEX(Calculator!$E$6:$E$23,MATCH("WND",Calculator!$A$6:$A$23,0)),0)/20))) -> 1 | P6: =INDEX(J6:N6,O6)*(1+(IFERROR(G6/10*INDEX(Calculator!$E$6:$E$23,MATCH(F6,Calculator!$A$6:$A$23,0))/100,0)+IFERROR(I6/10*INDEX(Calculator!$E$6:$E$23,MATCH(H6,Calculator!$A$6:$A$23,0))/100,0))*(1+Constants!$B$25*Calculator!$C$28))*(1+Calculator!$C$45)*(1-(1-MIN(0.5,Constants!$B$26*Calculator!$C$28))*Constants!$B$6) -> 20.4765
A7: Arc Beam | B7: Oath: Arcwarder | C7: Combat | D7: O | E7: after Oath: Arcwarder | G7: 0 | I7: 0
A8: Arc Suit | B8: Oath: Arcwarder | C8: Support | D8: O | E8: after Oath: Arcwarder | G8: 0 | I8: 0
A9: Arc Wave | B9: Oath: Arcwarder | C9: Combat | D9: O | E9: after Oath: Arcwarder | G9: 0 | I9: 0
A10: Ardour Slicer | B10: Oath: Soulbreaker | C10: Combat | D10: O | E10: after Oath: Soulbreaker | G10: 0 | I10: 0
A11: Ascension | B11: Oath: Starkindred | C11: Combat | D11: O | E11: after Oath: Starkindred | G11: 0 | I11: 0
A12: Ash Slam | B12: FLM + STR | C12: Combat | D12: N | E12: FLM 50 · STR 20 | F12: FLM | G12: 2.75 | I12: 0 | J12: 16 | K12: 22.4 | L12: 28.8 | M12: 35.2 | N12: 41.6 | O12: =MAX(1,MIN(5,1+INT(IFERROR(INDEX(Calculator!$E$6:$E$23,MATCH("FLM",Calculator!$A$6:$A$23,0)),0)/20))) -> 1 | P12: =INDEX(J12:N12,O12)*(1+(IFERROR(G12/10*INDEX(Calculator!$E$6:$E$23,MATCH(F12,Calculator!$A$6:$A$23,0))/100,0)+IFERROR(I12/10*INDEX(Calculator!$E$6:$E$23,MATCH(H12,Calculator!$A$6:$A$23,0))/100,0))*(1+Constants!$B$25*Calculator!$C$28))*(1+Calculator!$C$45)*(1-(1-MIN(0.5,Constants!$B$26*Calculator!$C$28))*Constants!$B$6) -> 14.892
A13: Astral Wind | B13: WND | C13: Combat | D13: N | E13: WND 50 | F13: WND | G13: 2.75 | I13: 0 | J13: 21.25 | K13: 26.75 | L13: 32.25 | M13: 37.75 | N13: 43.25 | O13: =MAX(1,MIN(5,1+INT(IFERROR(INDEX(Calculator!$E$6:$E$23,MATCH("WND",Calculator!$A$6:$A$23,0)),0)/20))) -> 1 | P13: =INDEX(J13:N13,O13)*(1+(IFERROR(G13/10*INDEX(Calculator!$E$6:$E$23,MATCH(F13,Calculator!$A$6:$A$23,0))/100,0)+IFERROR(I13/10*INDEX(Calculator!$E$6:$E$23,MATCH(H13,Calculator!$A$6:$A$23,0))/100,0))*(1+Constants!$B$25*Calculator!$C$28))*(1+Calculator!$C$45)*(1-(1-MIN(0.5,Constants!$B$26*Calculator!$C$28))*Constants!$B$6) -> 19.778437
A14: Beast Burrow | B14: Monster | C14: Mobility | D14: M | E14: no stat requirement | G14: 0 | I14: 0
A15: Blade of Saints | B15: Oath: Saintsworn | C15: Combat | D15: O | E15: after Oath: Saintsworn | G15: 0 | I15: 0
A16: Blinding Dawn | B16: Oath: Dawnwalker | C16: Combat | D16: O | E16: after Oath: Dawnwalker | G16: 0 | I16: 0
A17: Blood Orb | B17: BLD | C17: Combat | D17: N | E17: BLD 1 | F17: BLD | G17: 2.75 | I17: 0 | J17: 14.5 | K17: 19 | L17: 23.5 | M17: 28 | N17: 32.5 | O17: =MAX(1,MIN(5,1+INT(IFERROR(INDEX(Calculator!$E$6:$E$23,MATCH("BLD",Calculator!$A$6:$A$23,0)),0)/20))) -> 1 | P17: =INDEX(J17:N17,O17)*(1+(IFERROR(G17/10*INDEX(Calculator!$E$6:$E$23,MATCH(F17,Calculator!$A$6:$A$23,0))/100,0)+IFERROR(I17/10*INDEX(Calculator!$E$6:$E$23,MATCH(H17,Calculator!$A$6:$A$23,0))/100,0))*(1+Constants!$B$25*Calculator!$C$28))*(1+Calculator!$C$45)*(1-(1-MIN(0.5,Constants!$B$26*Calculator!$C$28))*Constants!$B$6) -> 13.495875
A18: Blood Stakes | B18: BLD | C18: Combat | D18: N | E18: BLD 20 | F18: BLD | G18: 2.75 | I18: 0 | J18: 25 | K18: 36 | L18: 49 | M18: 64 | N18: 81 | O18: =MAX(1,MIN(5,1+INT(IFERROR(INDEX(Calculator!$E$6:$E$23,MATCH("BLD",Calculator!$A$6:$A$23,0)),0)/20))) -> 1 | P18: =INDEX(J18:N18,O18)*(1+(IFERROR(G18/10*INDEX(Calculator!$E$6:$E$23,MATCH(F18,Calculator!$A$6:$A$23,0))/100,0)+IFERROR(I18/10*INDEX(Calculator!$E$6:$E$23,MATCH(H18,Calculator!$A$6:$A$23,0))/100,0))*(1+Constants!$B$25*Calculator!$C$28))*(1+Calculator!$C$45)*(1-(1-MIN(0.5,Constants!$B$26*Calculator!$C$28))*Constants!$B$6) -> 23.26875
A19: Blood Wisp | B19: BLD | C19: Wildcard | D19: N | E19: BLD 30 | G19: 0 | I19: 0
A20: Bloodcurdle | B20: BLD | C20: Combat | D20: N | E20: BLD 50 | F20: BLD | G20: 2.75 | I20: 0 | J20: 17.4 | K20: 23.8 | L20: 31.2 | M20: 39.6 | N20: 49 | O20: =MAX(1,MIN(5,1+INT(IFERROR(INDEX(Calculator!$E$6:$E$23,MATCH("BLD",Calculator!$A$6:$A$23,0)),0)/20))) -> 1 | P20: =INDEX(J20:N20,O20)*(1+(IFERROR(G20/10*INDEX(Calculator!$E$6:$E$23,MATCH(F20,Calculator!$A$6:$A$23,0))/100,0)+IFERROR(I20/10*INDEX(Calculator!$E$6:$E$23,MATCH(H20,Calculator!$A$6:$A$23,0))/100,0))*(1+Constants!$B$25*Calculator!$C$28))*(1+Calculator!$C$45)*(1-(1-MIN(0.5,Constants!$B$26*Calculator!$C$28))*Constants!$B$6) -> 16.19505
A21: Bloodedge | B21: BLD | C21: Combat | D21: N | E21: BLD 20 | F21: BLD | G21: 2.75 | I21: 0 | J21: 16 | K21: 20 | L21: 24 | M21: 28 | N21: 32 | O21: =MAX(1,MIN(5,1+INT(IFERROR(INDEX(Calculator!$E$6:$E$23,MATCH("BLD",Calculator!$A$6:$A$23,0)),0)/20))) -> 1 | P21: =INDEX(J21:N21,O21)*(1+(IFERROR(G21/10*INDEX(Calculator!$E$6:$E$23,MATCH(F21,Calculator!$A$6:$A$23,0))/100,0)+IFERROR(I21/10*INDEX(Calculator!$E$6:$E$23,MATCH(H21,Calculator!$A$6:$A$23,0))/100,0))*(1+Constants!$B$25*Calculator!$C$28))*(1+Calculator!$C$45)*(1-(1-MIN(0.5,Constants!$B$26*Calculator!$C$28))*Constants!$B$6) -> 14.892
A22: Bloodtide Ritual | B22: BLD | C22: Combat | D22: N | E22: BLD 50 | F22: BLD | G22: 2.75 | I22: 0 | J22: 42 | K22: 47 | L22: 52 | M22: 57 | N22: 62 | O22: =MAX(1,MIN(5,1+INT(IFERROR(INDEX(Calculator!$E$6:$E$23,MATCH("BLD",Calculator!$A$6:$A$23,0)),0)/20))) -> 1 | P22: =INDEX(J22:N22,O22)*(1+(IFERROR(G22/10*INDEX(Calculator!$E$6:$E$23,MATCH(F22,Calculator!$A$6:$A$23,0))/100,0)+IFERROR(I22/10*INDEX(Calculator!$E$6:$E$23,MATCH(H22,Calculator!$A$6:$A$23,0))/100,0))*(1+Constants!$B$25*Calculator!$C$28))*(1+Calculator!$C$45)*(1-(1-MIN(0.5,Constants!$B$26*Calculator!$C$28))*Constants!$B$6) -> 39.0915
A23: Bolt Piercer | B23: LTN | C23: Combat | D23: N | E23: LTN 30 | F23: LTN | G23: 2.75 | I23: 0 | J23: 15 | K23: 16 | L23: 17 | M23: 18 | N23: 19 | O23: =MAX(1,MIN(5,1+INT(IFERROR(INDEX(Calculator!$E$6:$E$23,MATCH("LTN",Calculator!$A$6:$A$23,0)),0)/20))) -> 2 | P23: =INDEX(J23:N23,O23)*(1+(IFERROR(G23/10*INDEX(Calculator!$E$6:$E$23,MATCH(F23,Calculator!$A$6:$A$23,0))/100,0)+IFERROR(I23/10*INDEX(Calculator!$E$6:$E$23,MATCH(H23,Calculator!$A$6:$A$23,0))/100,0))*(1+Constants!$B$25*Calculator!$C$28))*(1+Calculator!$C$45)*(1-(1-MIN(0.5,Constants!$B$26*Calculator!$C$28))*Constants!$B$6) -> 16.027217
A24: Bone Wisp | B24: Monster | C24: Wildcard | D24: M | E24: no stat requirement | G24: 0 | I24: 0
A25: Brace | B25: FTD | C25: Support | D25: N | E25: FTD 75 | G25: 0 | I25: 0
A26: Brachial Spear | B26: Monster | C26: Combat | D26: M | E26: no stat requirement | G26: 0 | I26: 0
A27: Burning Servants | B27: FLM | C27: Combat | D27: N | E27: FLM 1 | F27: FLM | G27: 2.75 | I27: 0 | J27: 44 | K27: 48.4 | L27: 52.8 | M27: 57.2 | N27: 61.6 | O27: =MAX(1,MIN(5,1+INT(IFERROR(INDEX(Calculator!$E$6:$E$23,MATCH("FLM",Calculator!$A$6:$A$23,0)),0)/20))) -> 1 | P27: =INDEX(J27:N27,O27)*(1+(IFERROR(G27/10*INDEX(Calculator!$E$6:$E$23,MATCH(F27,Calculator!$A$6:$A$23,0))/100,0)+IFERROR(I27/10*INDEX(Calculator!$E$6:$E$23,MATCH(H27,Calculator!$A$6:$A$23,0))/100,0))*(1+Constants!$B$25*Calculator!$C$28))*(1+Calculator!$C$45)*(1-(1-MIN(0.5,Constants!$B$26*Calculator!$C$28))*Constants!$B$6) -> 40.953
A28: Caltrops | B28: IRN | C28: Combat | D28: N | E28: IRN 30 | F28: IRN | G28: 2.75 | I28: 0 | J28: 32 | K28: 29.9 | L28: 33.8 | M28: 37.7 | N28: 41.6 | O28: =MAX(1,MIN(5,1+INT(IFERROR(INDEX(Calculator!$E$6:$E$23,MATCH("IRN",Calculator!$A$6:$A$23,0)),0)/20))) -> 5 | P28: =INDEX(J28:N28,O28)*(1+(IFERROR(G28/10*INDEX(Calculator!$E$6:$E$23,MATCH(F28,Calculator!$A$6:$A$23,0))/100,0)+IFERROR(I28/10*INDEX(Calculator!$E$6:$E$23,MATCH(H28,Calculator!$A$6:$A$23,0))/100,0))*(1+Constants!$B$25*Calculator!$C$28))*(1+Calculator!$C$45)*(1-(1-MIN(0.5,Constants!$B$26*Calculator!$C$28))*Constants!$B$6) -> 50.793783
A29: Ceaseless Slashes | B29: LHT | C29: Combat | D29: N | E29: LHT 50 | G29: 0 | I29: 0
A30: Celestial Assault | B30: Oath: Starkindred | C30: Combat | D30: O | E30: after Oath: Starkindred | G30: 0 | I30: 0
A31: Chain Pull | B31: IRN | C31: Support | D31: N | E31: IRN 20 | F31: IRN | G31: 2.75 | I31: 0 | J31: 20 | K31: 22 | L31: 24 | M31: 26 | N31: 28 | O31: =MAX(1,MIN(5,1+INT(IFERROR(INDEX(Calculator!$E$6:$E$23,MATCH("IRN",Calculator!$A$6:$A$23,0)),0)/20))) -> 5 | P31: =INDEX(J31:N31,O31)*(1+(IFERROR(G31/10*INDEX(Calculator!$E$6:$E$23,MATCH(F31,Calculator!$A$6:$A$23,0))/100,0)+IFERROR(I31/10*INDEX(Calculator!$E$6:$E$23,MATCH(H31,Calculator!$A$6:$A$23,0))/100,0))*(1+Constants!$B$25*Calculator!$C$28))*(1+Calculator!$C$45)*(1-(1-MIN(0.5,Constants!$B$26*Calculator!$C$28))*Constants!$B$6) -> 34.188123
A32: Champion's Whirlthrow | B32: WND | C32: Combat | D32: N | E32: WND 30 | F32: WND | G32: 2.75 | I32: 0 | J32: 41 | K32: 46 | L32: 51 | M32: 56 | N32: 61 | O32: =MAX(1,MIN(5,1+INT(IFERROR(INDEX(Calculator!$E$6:$E$23,MATCH("WND",Calculator!$A$6:$A$23,0)),0)/20))) -> 1 | P32: =INDEX(J32:N32,O32)*(1+(IFERROR(G32/10*INDEX(Calculator!$E$6:$E$23,MATCH(F32,Calculator!$A$6:$A$23,0))/100,0)+IFERROR(I32/10*INDEX(Calculator!$E$6:$E$23,MATCH(H32,Calculator!$A$6:$A$23,0))/100,0))*(1+Constants!$B$25*Calculator!$C$28))*(1+Calculator!$C$45)*(1-(1-MIN(0.5,Constants!$B$26*Calculator!$C$28))*Constants!$B$6) -> 38.16075
A33: Close Shave | B33: Oath: Fadetrimmer | C33: Combat | D33: O | E33: after Oath: Fadetrimmer | G33: 0 | I33: 0
A34: Clutching Shadow | B34: SDW | C34: Combat | D34: N | E34: SDW 1 | F34: SDW | G34: 2.75 | I34: 0 | J34: 24 | K34: 28.2 | L34: 32.4 | M34: 36.6 | N34: 40.8 | O34: =MAX(1,MIN(5,1+INT(IFERROR(INDEX(Calculator!$E$6:$E$23,MATCH("SDW",Calculator!$A$6:$A$23,0)),0)/20))) -> 1 | P34: =INDEX(J34:N34,O34)*(1+(IFERROR(G34/10*INDEX(Calculator!$E$6:$E$23,MATCH(F34,Calculator!$A$6:$A$23,0))/100,0)+IFERROR(I34/10*INDEX(Calculator!$E$6:$E$23,MATCH(H34,Calculator!$A$6:$A$23,0))/100,0))*(1+Constants!$B$25*Calculator!$C$28))*(1+Calculator!$C$45)*(1-(1-MIN(0.5,Constants!$B$26*Calculator!$C$28))*Constants!$B$6) -> 22.338
A35: Coral Burst | B35: Monster | C35: Combat | D35: M | E35: no stat requirement | G35: 0 | I35: 0
A36: Crimson Rain | B36: BLD | C36: Combat | D36: N | E36: BLD 30 | F36: BLD | G36: 2.75 | I36: 0 | J36: 14.25 | K36: 16.5 | L36: 18.75 | M36: 21 | N36: 46.5 | O36: =MAX(1,MIN(5,1+INT(IFERROR(INDEX(Calculator!$E$6:$E$23,MATCH("BLD",Calculator!$A$6:$A$23,0)),0)/20))) -> 1 | P36: =INDEX(J36:N36,O36)*(1+(IFERROR(G36/10*INDEX(Calculator!$E$6:$E$23,MATCH(F36,Calculator!$A$6:$A$23,0))/100,0)+IFERROR(I36/10*INDEX(Calculator!$E$6:$E$23,MATCH(H36,Calculator!$A$6:$A$23,0))/100,0))*(1+Constants!$B$25*Calculator!$C$28))*(1+Calculator!$C$45)*(1-(1-MIN(0.5,Constants!$B$26*Calculator!$C$28))*Constants!$B$6) -> 13.263188
A37: Crimson Surge | B37: BLD | C37: Combat | D37: N | E37: BLD 30 | F37: BLD | G37: 2.75 | I37: 0 | J37: 24 | K37: 30 | L37: 36 | M37: 42 | N37: 48 | O37: =MAX(1,MIN(5,1+INT(IFERROR(INDEX(Calculator!$E$6:$E$23,MATCH("BLD",Calculator!$A$6:$A$23,0)),0)/20))) -> 1 | P37: =INDEX(J37:N37,O37)*(1+(IFERROR(G37/10*INDEX(Calculator!$E$6:$E$23,MATCH(F37,Calculator!$A$6:$A$23,0))/100,0)+IFERROR(I37/10*INDEX(Calculator!$E$6:$E$23,MATCH(H37,Calculator!$A$6:$A$23,0))/100,0))*(1+Constants!$B$25*Calculator!$C$28))*(1+Calculator!$C$45)*(1-(1-MIN(0.5,Constants!$B$26*Calculator!$C$28))*Constants!$B$6) -> 22.338
A38: Crucifixion | B38: BLD | C38: Combat | D38: N | E38: BLD 1 | F38: BLD | G38: 2.75 | I38: 0 | J38: 16 | K38: 22 | L38: 28 | M38: 34 | N38: 40 | O38: =MAX(1,MIN(5,1+INT(IFERROR(INDEX(Calculator!$E$6:$E$23,MATCH("BLD",Calculator!$A$6:$A$23,0)),0)/20))) -> 1 | P38: =INDEX(J38:N38,O38)*(1+(IFERROR(G38/10*INDEX(Calculator!$E$6:$E$23,MATCH(F38,Calculator!$A$6:$A$23,0))/100,0)+IFERROR(I38/10*INDEX(Calculator!$E$6:$E$23,MATCH(H38,Calculator!$A$6:$A$23,0))/100,0))*(1+Constants!$B$25*Calculator!$C$28))*(1+Calculator!$C$45)*(1-(1-MIN(0.5,Constants!$B$26*Calculator!$C$28))*Constants!$B$6) -> 14.892
A39: Crystal Impale | B39: ICE | C39: Combat | D39: N | E39: ICE 30 · after Glass Path: Crystallization | F39: ICE | G39: 2.75 | I39: 0 | J39: 23.3 | K39: 28.3 | L39: 33.3 | M39: 38.3 | N39: 43.3 | O39: =MAX(1,MIN(5,1+INT(IFERROR(INDEX(Calculator!$E$6:$E$23,MATCH("ICE",Calculator!$A$6:$A$23,0)),0)/20))) -> 1 | P39: =INDEX(J39:N39,O39)*(1+(IFERROR(G39/10*INDEX(Calculator!$E$6:$E$23,MATCH(F39,Calculator!$A$6:$A$23,0))/100,0)+IFERROR(I39/10*INDEX(Calculator!$E$6:$E$23,MATCH(H39,Calculator!$A$6:$A$23,0))/100,0))*(1+Constants!$B$25*Calculator!$C$28))*(1+Calculator!$C$45)*(1-(1-MIN(0.5,Constants!$B$26*Calculator!$C$28))*Constants!$B$6) -> 21.686475
A40: Crystal Knee | B40: ICE | C40: Combat | D40: N | E40: ICE 30 · after Glass Path: Crystallization | F40: ICE | G40: 2.75 | I40: 0 | J40: 35 | K40: 38 | L40: 41 | M40: 44 | N40: 47 | O40: =MAX(1,MIN(5,1+INT(IFERROR(INDEX(Calculator!$E$6:$E$23,MATCH("ICE",Calculator!$A$6:$A$23,0)),0)/20))) -> 1 | P40: =INDEX(J40:N40,O40)*(1+(IFERROR(G40/10*INDEX(Calculator!$E$6:$E$23,MATCH(F40,Calculator!$A$6:$A$23,0))/100,0)+IFERROR(I40/10*INDEX(Calculator!$E$6:$E$23,MATCH(H40,Calculator!$A$6:$A$23,0))/100,0))*(1+Constants!$B$25*Calculator!$C$28))*(1+Calculator!$C$45)*(1-(1-MIN(0.5,Constants!$B$26*Calculator!$C$28))*Constants!$B$6) -> 32.57625
...

Sheet Weapons
A1: Weapon | B1: Type | C1: Requirement | D1: Base damage | E1: PEN | F1: Scale stat 1 | G1: Coef 1 | H1: Scale stat 2 | I1: Coef 2 | J1: Scale stat 3 | K1: Coef 3 | L1: Hit with Calculator stats
A2: Acheron's Warspear | B2: Spear | C2: MED 40 | D2: 18 | E2: 0.15 | F2: MED | G2: 6 | I2: 0 | K2: 0 | L2: =D2*(1+0.75*(IFERROR(G2*INDEX(Calculator!$E$6:$E$23,MATCH(F2,Calculator!$A$6:$A$23,0)),0)+IFERROR(I2*INDEX(Calculator!$E$6:$E$23,MATCH(H2,Calculator!$A$6:$A$23,0)),0)+IFERROR(K2*INDEX(Calculator!$E$6:$E$23,MATCH(J2,Calculator!$A$6:$A$23,0)),0))*(1+Constants!$B$23*Calculator!$C$27)/1000)*(1+Calculator!$C$45+Calculator!$C$37)*Calculator!$C$39*(1-(1-MIN(Calculator!$C$44,MIN(1,E2+Calculator!$E$6/10*Constants!$B$16+Calculator!$C$36+Calculator!$C$40+Constants!$B$24*Calculator!$C$27)))*Constants!$B$6) -> 27.294752
A3: Adretian Axe | B3: Greataxe | C3: HVY 35 | D3: 24 | E3: 0 | F3: HVY | G3: 7 | I3: 0 | K3: 0 | L3: =D3*(1+0.75*(IFERROR(G3*INDEX(Calculator!$E$6:$E$23,MATCH(F3,Calculator!$A$6:$A$23,0)),0)+IFERROR(I3*INDEX(Calculator!$E$6:$E$23,MATCH(H3,Calculator!$A$6:$A$23,0)),0)+IFERROR(K3*INDEX(Calculator!$E$6:$E$23,MATCH(J3,Calculator!$A$6:$A$23,0)),0))*(1+Constants!$B$23*Calculator!$C$27)/1000)*(1+Calculator!$C$45+Calculator!$C$37)*Calculator!$C$39*(1-(1-MIN(Calculator!$C$44,MIN(1,E3+Calculator!$E$6/10*Constants!$B$16+Calculator!$C$36+Calculator!$C$40+Constants!$B$24*Calculator!$C$27)))*Constants!$B$6) -> 22.53996
A4: Alloyed Adretian Axe | B4: Greataxe | C4: HVY 75 | D4: 24 | E4: 0.1 | F4: HVY | G4: 8 | I4: 0 | K4: 0 | L4: =D4*(1+0.75*(IFERROR(G4*INDEX(Calculator!$E$6:$E$23,MATCH(F4,Calculator!$A$6:$A$23,0)),0)+IFERROR(I4*INDEX(Calculator!$E$6:$E$23,MATCH(H4,Calculator!$A$6:$A$23,0)),0)+IFERROR(K4*INDEX(Calculator!$E$6:$E$23,MATCH(J4,Calculator!$A$6:$A$23,0)),0))*(1+Constants!$B$23*Calculator!$C$27)/1000)*(1+Calculator!$C$45+Calculator!$C$37)*Calculator!$C$39*(1-(1-MIN(Calculator!$C$44,MIN(1,E4+Calculator!$E$6/10*Constants!$B$16+Calculator!$C$36+Calculator!$C$40+Constants!$B$24*Calculator!$C$27)))*Constants!$B$6) -> 23.45796
A5: Alloyed Canorian Axe | B5: Greataxe | C5: HVY 75 | D5: 24 | E5: 0.2 | F5: HVY | G5: 9 | I5: 0 | K5: 0 | L5: =D5*(1+0.75*(IFERROR(G5*INDEX(Calculator!$E$6:$E$23,MATCH(F5,Calculator!$A$6:$A$23,0)),0)+IFERROR(I5*INDEX(Calculator!$E$6:$E$23,MATCH(H5,Calculator!$A$6:$A$23,0)),0)+IFERROR(K5*INDEX(Calculator!$E$6:$E$23,MATCH(J5,Calculator!$A$6:$A$23,0)),0))*(1+Constants!$B$23*Calculator!$C$27)/1000)*(1+Calculator!$C$45+Calculator!$C$37)*Calculator!$C$39*(1-(1-MIN(Calculator!$C$44,MIN(1,E5+Calculator!$E$6/10*Constants!$B$16+Calculator!$C$36+Calculator!$C$40+Constants!$B$24*Calculator!$C$27)))*Constants!$B$6) -> 24.37596
A6: Alloyed Cavalry Saber | B6: Sword | C6: MED 75 | D6: 22.5 | E6: 0.1 | F6: MED | G6: 5.5 | I6: 0 | K6: 0 | L6: =D6*(1+0.75*(IFERROR(G6*INDEX(Calculator!$E$6:$E$23,MATCH(F6,Calculator!$A$6:$A$23,0)),0)+IFERROR(I6*INDEX(Calculator!$E$6:$E$23,MATCH(H6,Calculator!$A$6:$A$23,0)),0)+IFERROR(K6*INDEX(Calculator!$E$6:$E$23,MATCH(J6,Calculator!$A$6:$A$23,0)),0))*(1+Constants!$B$23*Calculator!$C$27)/1000)*(1+Calculator!$C$45+Calculator!$C$37)*Calculator!$C$39*(1-(1-MIN(Calculator!$C$44,MIN(1,E6+Calculator!$E$6/10*Constants!$B$16+Calculator!$C$36+Calculator!$C$40+Constants!$B$24*Calculator!$C$27)))*Constants!$B$6) -> 32.507674
A7: Alloyed Crescent Cleaver | B7: Greatsword | C7: HVY 75 · STR 10 | D7: 22 | E7: 0 | F7: HVY | G7: 10 | I7: 0 | K7: 0 | L7: =D7*(1+0.75*(IFERROR(G7*INDEX(Calculator!$E$6:$E$23,MATCH(F7,Calculator!$A$6:$A$23,0)),0)+IFERROR(I7*INDEX(Calculator!$E$6:$E$23,MATCH(H7,Calculator!$A$6:$A$23,0)),0)+IFERROR(K7*INDEX(Calculator!$E$6:$E$23,MATCH(J7,Calculator!$A$6:$A$23,0)),0))*(1+Constants!$B$23*Calculator!$C$27)/1000)*(1+Calculator!$C$45+Calculator!$C$37)*Calculator!$C$39*(1-(1-MIN(Calculator!$C$44,MIN(1,E7+Calculator!$E$6/10*Constants!$B$16+Calculator!$C$36+Calculator!$C$40+Constants!$B$24*Calculator!$C$27)))*Constants!$B$6) -> 20.66163
A8: Alloyed Dawnshot | B8: Pistol | C8: LHT 75 | D8: 16 | E8: 0.05 | F8: LHT | G8: 12 | I8: 0 | K8: 0 | L8: =D8*(1+0.75*(IFERROR(G8*INDEX(Calculator!$E$6:$E$23,MATCH(F8,Calculator!$A$6:$A$23,0)),0)+IFERROR(I8*INDEX(Calculator!$E$6:$E$23,MATCH(H8,Calculator!$A$6:$A$23,0)),0)+IFERROR(K8*INDEX(Calculator!$E$6:$E$23,MATCH(J8,Calculator!$A$6:$A$23,0)),0))*(1+Constants!$B$23*Calculator!$C$27)/1000)*(1+Calculator!$C$45+Calculator!$C$37)*Calculator!$C$39*(1-(1-MIN(Calculator!$C$44,MIN(1,E8+Calculator!$E$6/10*Constants!$B$16+Calculator!$C$36+Calculator!$C$40+Constants!$B$24*Calculator!$C$27)))*Constants!$B$6) -> 15.33264
A9: Alloyed Falchion | B9: Sword | C9: MED 75 | D9: 18 | E9: 0.2 | F9: MED | G9: 7 | I9: 0 | K9: 0 | L9: =D9*(1+0.75*(IFERROR(G9*INDEX(Calculator!$E$6:$E$23,MATCH(F9,Calculator!$A$6:$A$23,0)),0)+IFERROR(I9*INDEX(Calculator!$E$6:$E$23,MATCH(H9,Calculator!$A$6:$A$23,0)),0)+IFERROR(K9*INDEX(Calculator!$E$6:$E$23,MATCH(J9,Calculator!$A$6:$A$23,0)),0))*(1+Constants!$B$23*Calculator!$C$27)/1000)*(1+Calculator!$C$45+Calculator!$C$37)*Calculator!$C$39*(1-(1-MIN(Calculator!$C$44,MIN(1,E9+Calculator!$E$6/10*Constants!$B$16+Calculator!$C$36+Calculator!$C$40+Constants!$B$24*Calculator!$C$27)))*Constants!$B$6) -> 29.408011
A10: Alloyed Forge Greathammer | B10: Greathammer | C10: HVY 75 · STR 10 | D10: 25.5 | E10: 0 | F10: HVY | G10: 8 | I10: 0 | K10: 0 | L10: =D10*(1+0.75*(IFERROR(G10*INDEX(Calculator!$E$6:$E$23,MATCH(F10,Calculator!$A$6:$A$23,0)),0)+IFERROR(I10*INDEX(Calculator!$E$6:$E$23,MATCH(H10,Calculator!$A$6:$A$23,0)),0)+IFERROR(K10*INDEX(Calculator!$E$6:$E$23,MATCH(J10,Calculator!$A$6:$A$23,0)),0))*(1+Constants!$B$23*Calculator!$C$27)/1000)*(1+Calculator!$C$45+Calculator!$C$37)*Calculator!$C$39*(1-(1-MIN(Calculator!$C$44,MIN(1,E10+Calculator!$E$6/10*Constants!$B$16+Calculator!$C$36+Calculator!$C$40+Constants!$B$24*Calculator!$C$27)))*Constants!$B$6) -> 23.948708
A11: Alloyed Halberd | B11: Greataxe | C11: HVY 75 | D11: 24 | E11: 0.15 | F11: HVY | G11: 8 | I11: 0 | K11: 0 | L11: =D11*(1+0.75*(IFERROR(G11*INDEX(Calculator!$E$6:$E$23,MATCH(F11,Calculator!$A$6:$A$23,0)),0)+IFERROR(I11*INDEX(Calculator!$E$6:$E$23,MATCH(H11,Calculator!$A$6:$A$23,0)),0)+IFERROR(K11*INDEX(Calculator!$E$6:$E$23,MATCH(J11,Calculator!$A$6:$A$23,0)),0))*(1+Constants!$B$23*Calculator!$C$27)/1000)*(1+Calculator!$C$45+Calculator!$C$37)*Calculator!$C$39*(1-(1-MIN(Calculator!$C$44,MIN(1,E11+Calculator!$E$6/10*Constants!$B$16+Calculator!$C$36+Calculator!$C$40+Constants!$B$24*Calculator!$C$27)))*Constants!$B$6) -> 23.91696
A12: Alloyed Inheritor | B12: Greatsword | C12: HVY 75 · STR 10 | D12: 24 | E12: 0.15 | F12: HVY | G12: 8 | I12: 0 | K12: 0 | L12: =D12*(1+0.75*(IFERROR(G12*INDEX(Calculator!$E$6:$E$23,MATCH(F12,Calculator!$A$6:$A$23,0)),0)+IFERROR(I12*INDEX(Calculator!$E$6:$E$23,MATCH(H12,Calculator!$A$6:$A$23,0)),0)+IFERROR(K12*INDEX(Calculator!$E$6:$E$23,MATCH(J12,Calculator!$A$6:$A$23,0)),0))*(1+Constants!$B$23*Calculator!$C$27)/1000)*(1+Calculator!$C$45+Calculator!$C$37)*Calculator!$C$39*(1-(1-MIN(Calculator!$C$44,MIN(1,E12+Calculator!$E$6/10*Constants!$B$16+Calculator!$C$36+Calculator!$C$40+Constants!$B$24*Calculator!$C$27)))*Constants!$B$6) -> 23.91696
A13: Alloyed Katana | B13: Sword | C13: MED 75 | D13: 20 | E13: 0.1 | F13: MED | G13: 7 | I13: 0 | K13: 0 | L13: =D13*(1+0.75*(IFERROR(G13*INDEX(Calculator!$E$6:$E$23,MATCH(F13,Calculator!$A$6:$A$23,0)),0)+IFERROR(I13*INDEX(Calculator!$E$6:$E$23,MATCH(H13,Calculator!$A$6:$A$23,0)),0)+IFERROR(K13*INDEX(Calculator!$E$6:$E$23,MATCH(J13,Calculator!$A$6:$A$23,0)),0))*(1+Constants!$B$23*Calculator!$C$27)/1000)*(1+Calculator!$C$45+Calculator!$C$37)*Calculator!$C$39*(1-(1-MIN(Calculator!$C$44,MIN(1,E13+Calculator!$E$6/10*Constants!$B$16+Calculator!$C$36+Calculator!$C$40+Constants!$B$24*Calculator!$C$27)))*Constants!$B$6) -> 31.445004
... A30: Big Brother | B30: Dagger | C30: LHT 80 | D30: 15 | E30: 0.15 | F30: LHT | G30: 8 | I30: 0 | K30: 0 | L30: =D30*(1+0.75*(IFERROR(G30*INDEX(Calculator!$E$6:$E$23,MATCH(F30,Calculator!$A$6:$A$23,0)),0)+IFERROR(I30*INDEX(Calculator!$E$6:$E$23,MATCH(H30,Calculator!$A$6:$A$23,0)),0)+IFERROR(K30*INDEX(Calculator!$E$6:$E$23,MATCH(J30,Calculator!$A$6:$A$23,0)),0))*(1+Constants!$B$23*Calculator!$C$27)/1000)*(1+Calculator!$C$45+Calculator!$C$37)*Calculator!$C$39*(1-(1-MIN(Calculator!$C$44,MIN(1,E30+Calculator!$E$6/10*Constants!$B$16+Calculator!$C$36+Calculator!$C$40+Constants!$B$24*Calculator!$C$27)))*Constants!$B$6) -> 14.9481
A31: Black Death | B31: Spear | C31: MED 30 · Mind 50 · SDW 70 · Power 10 | D31: 16.5 | E31: 0.15 | F31: MED | G31: 2.5 | H31: MND | I31: 2 | J31: SDW | K31: 3 | L31: =D31*(1+0.75*(IFERROR(G31*INDEX(Calculator!$E$6:$E$23,MATCH(F31,Calculator!$A$6:$A$23,0)),0)+IFERROR(I31*INDEX(Calculator!$E$6:$E$23,MATCH(H31,Calculator!$A$6:$A$23,0)),0)+IFERROR(K31*INDEX(Calculator!$E$6:$E$23,MATCH(J31,Calculator!$A$6:$A$23,0)),0))*(1+Constants!$B$23*Calculator!$C$27)/1000)*(1+Calculator!$C$45+Calculator!$C$37)*Calculator!$C$39*(1-(1-MIN(Calculator!$C$44,MIN(1,E31+Calculator!$E$6/10*Constants!$B$16+Calculator!$C$36+Calculator!$C$40+Constants!$B$24*Calculator!$C$27)))*Constants!$B$6) -> 20.793704
A32: Bloodbane | B32: Greatsword | C32: HVY 60 · STR 30 | D32: 23 | E32: 0 | F32: HVY | G32: 7 | I32: 0 | K32: 0 | L32: =D32*(1+0.75*(IFERROR(G32*INDEX(Calculator!$E$6:$E$23,MATCH(F32,Calculator!$A$6:$A$23,0)),0)+IFERROR(I32*INDEX(Calculator!$E$6:$E$23,MATCH(H32,Calculator!$A$6:$A$23,0)),0)+IFERROR(K32*INDEX(Calculator!$E$6:$E$23,MATCH(J32,Calculator!$A$6:$A$23,0)),0))*(1+Constants!$B$23*Calculator!$C$27)/1000)*(1+Calculator!$C$45+Calculator!$C$37)*Calculator!$C$39*(1-(1-MIN(Calculator!$C$44,MIN(1,E32+Calculator!$E$6/10*Constants!$B$16+Calculator!$C$36+Calculator!$C$40+Constants!$B$24*Calculator!$C$27)))*Constants!$B$6) -> 21.600795
A33: Bloodfouler | B33: Greatsword | C33: HVY 50 · BLD 75 · Power 10 | D33: 19 | E33: 0.2 | F33: HVY | G33: 5 | H33: BLD | I33: 4 | K33: 0 | L33: =D33*(1+0.75*(IFERROR(G33*INDEX(Calculator!$E$6:$E$23,MATCH(F33,Calculator!$A$6:$A$23,0)),0)+IFERROR(I33*INDEX(Calculator!$E$6:$E$23,MATCH(H33,Calculator!$A$6:$A$23,0)),0)+IFERROR(K33*INDEX(Calculator!$E$6:$E$23,MATCH(J33,Calculator!$A$6:$A$23,0)),0))*(1+Constants!$B$23*Calculator!$C$27)/1000)*(1+Calculator!$C$45+Calculator!$C$37)*Calculator!$C$39*(1-(1-MIN(Calculator!$C$44,MIN(1,E33+Calculator!$E$6/10*Constants!$B$16+Calculator!$C$36+Calculator!$C$40+Constants!$B$24*Calculator!$C$27)))*Constants!$B$6) -> 19.297635
A34: Bloodtide Trident | B34: Spear | C34: MED 75 | D34: 18 | E34: 0.25 | F34: MED | G34: 6 | I34: 0 | K34: 0 | L34: =D34*(1+0.75*(IFERROR(G34*INDEX(Calculator!$E$6:$E$23,MATCH(F34,Calculator!$A$6:$A$23,0)),0)+IFERROR(I34*INDEX(Calculator!$E$6:$E$23,MATCH(H34,Calculator!$A$6:$A$23,0)),0)+IFERROR(K34*INDEX(Calculator!$E$6:$E$23,MATCH(J34,Calculator!$A$6:$A$23,0)),0))*(1+Constants!$B$23*Calculator!$C$27)/1000)*(1+Calculator!$C$45+Calculator!$C$37)*Calculator!$C$39*(1-(1-MIN(Calculator!$C$44,MIN(1,E34+Calculator!$E$6/10*Constants!$B$16+Calculator!$C$36+Calculator!$C$40+Constants!$B$24*Calculator!$C$27)))*Constants!$B$6) -> 28.342401
A35: Boltcrusher | B35: Greathammer | C35: HVY 55 · STR 20 · LTN 80 | D35: 23 | E35: 0.2 | F35: HVY | G35: 4.2 | H35: LTN | I35: 7 | K35: 0 | L35: =D35*(1+0.75*(IFERROR(G35*INDEX(Calculator!$E$6:$E$23,MATCH(F35,Calculator!$A$6:$A$23,0)),0)+IFERROR(I35*INDEX(Calculator!$E$6:$E$23,MATCH(H35,Calculator!$A$6:$A$23,0)),0)+IFERROR(K35*INDEX(Calculator!$E$6:$E$23,MATCH(J35,Calculator!$A$6:$A$23,0)),0))*(1+Constants!$B$23*Calculator!$C$27)/1000)*(1+Calculator!$C$45+Calculator!$C$37)*Calculator!$C$39*(1-(1-MIN(Calculator!$C$44,MIN(1,E35+Calculator!$E$6/10*Constants!$B$16+Calculator!$C$36+Calculator!$C$40+Constants!$B$24*Calculator!$C$27)))*Constants!$B$6) -> 26.759919
A36: Broodalloy Cestus | B36: Fist | C36: LHT 85 | D36: 15.5 | E36: 0.2 | F36: LHT | G36: 9 | I36: 0 | K36: 0 | L36: =D36*(1+0.75*(IFERROR(G36*INDEX(Calculator!$E$6:$E$23,MATCH(F36,Calculator!$A$6:$A$23,0)),0)+IFERROR(I36*INDEX(Calculator!$E$6:$E$23,MATCH(H36,Calculator!$A$6:$A$23,0)),0)+IFERROR(K36*INDEX(Calculator!$E$6:$E$23,MATCH(J36,Calculator!$A$6:$A$23,0)),0))*(1+Constants!$B$23*Calculator!$C$27)/1000)*(1+Calculator!$C$45+Calculator!$C$37)*Calculator!$C$39*(1-(1-MIN(Calculator!$C$44,MIN(1,E36+Calculator!$E$6/10*Constants!$B$16+Calculator!$C$36+Calculator!$C$40+Constants!$B$24*Calculator!$C$27)))*Constants!$B$6) -> 15.742807
A37: Calamity Cinnabar | B37: Greatsword | C37: HVY 40 · SDW 75 · Power 10 | D37: 22 | E37: 0 | F37: HVY | G37: 4 | H37: SDW | I37: 9 | K37: 0 | L37: =D37*(1+0.75*(IFERROR(G37*INDEX(Calculator!$E$6:$E$23,MATCH(F37,Calculator!$A$6:$A$23,0)),0)+IFERROR(I37*INDEX(Calculator!$E$6:$E$23,MATCH(H37,Calculator!$A$6:$A$23,0)),0)+IFERROR(K37*INDEX(Calculator!$E$6:$E$23,MATCH(J37,Calculator!$A$6:$A$23,0)),0))*(1+Constants!$B$23*Calculator!$C$27)/1000)*(1+Calculator!$C$45+Calculator!$C$37)*Calculator!$C$39*(1-(1-MIN(Calculator!$C$44,MIN(1,E37+Calculator!$E$6/10*Constants!$B$16+Calculator!$C$36+Calculator!$C$40+Constants!$B$24*Calculator!$C$27)))*Constants!$B$6) -> 20.66163
A38: Canor Fang | B38: Dagger | C38: LHT 40 | D38: 11 | E38: 0.05 | F38: LHT | G38: 10 | I38: 0 | K38: 0 | L38: =D38*(1+0.75*(IFERROR(G38*INDEX(Calculator!$E$6:$E$23,MATCH(F38,Calculator!$A$6:$A$23,0)),0)+IFERROR(I38*INDEX(Calculator!$E$6:$E$23,MATCH(H38,Calculator!$A$6:$A$23,0)),0)+IFERROR(K38*INDEX(Calculator!$E$6:$E$23,MATCH(J38,Calculator!$A$6:$A$23,0)),0))*(1+Constants!$B$23*Calculator!$C$27)/1000)*(1+Calculator!$C$45+Calculator!$C$37)*Calculator!$C$39*(1-(1-MIN(Calculator!$C$44,MIN(1,E38+Calculator!$E$6/10*Constants!$B$16+Calculator!$C$36+Calculator!$C$40+Constants!$B$24*Calculator!$C$27)))*Constants!$B$6) -> 10.54119
A39: Canorian Axe | B39: Greataxe | C39: HVY 35 | D39: 24 | E39: 0 | F39: HVY | G39: 7 | I39: 0 | K39: 0 | L39: =D39*(1+0.75*(IFERROR(G39*INDEX(Calculator!$E$6:$E$23,MATCH(F39,Calculator!$A$6:$A$23,0)),0)+IFERROR(I39*INDEX(Calculator!$E$6:$E$23,MATCH(H39,Calculator!$A$6:$A$23,0)),0)+IFERROR(K39*INDEX(Calculator!$E$6:$E$23,MATCH(J39,Calculator!$A$6:$A$23,0)),0))*(1+Constants!$B$23*Calculator!$C$27)/1000)*(1+Calculator!$C$45+Calculator!$C$37)*Calculator!$C$39*(1-(1-MIN(Calculator!$C$44,MIN(1,E39+Calculator!$E$6/10*Constants!$B$16+Calculator!$C$36+Calculator!$C$40+Constants!$B$24*Calculator!$C$27)))*Constants!$B$6) -> 22.53996
A40: Cavalry Saber | B40: Sword | C40: MED 40 | D40: 21 | E40: 0 | F40: MED | G40: 5 | I40: 0 | K40: 0 | L40: =D40*(1+0.75*(IFERROR(G40*INDEX(Calculator!$E$6:$E$23,MATCH(F40,Calculator!$A$6:$A$23,0)),0)+IFERROR(I40*INDEX(Calculator!$E$6:$E$23,MATCH(H40,Calculator!$A$6:$A$23,0)),0)+IFERROR(K40*INDEX(Calculator!$E$6:$E$23,MATCH(J40,Calculator!$A$6:$A$23,0)),0))*(1+Constants!$B$23*Calculator!$C$27)/1000)*(1+Calculator!$C$45+Calculator!$C$37)*Calculator!$C$39*(1-(1-MIN(Calculator!$C$44,MIN(1,E40+Calculator!$E$6/10*Constants!$B$16+Calculator!$C$36+Calculator!$C$40+Constants!$B$24*Calculator!$C$27)))*Constants!$B$6) -> 28.295821
A41: Central Dirk | B41: Dagger | C41: LHT 50 | D41: 16 | E41: 0.05 | F41: LHT | G41: 7 | I41: 0 | K41: 0 | L41: =D41*(1+0.75*(IFERROR(G41*INDEX(Calculator!$E$6:$E$23,MATCH(F41,Calculator!$A$6:$A$23,0)),0)+IFERROR(I41*INDEX(Calculator!$E$6:$E$23,MATCH(H41,Calculator!$A$6:$A$23,0)),0)+IFERROR(K41*INDEX(Calculator!$E$6:$E$23,MATCH(J41,Calculator!$A$6:$A$23,0)),0))*(1+Constants!$B$23*Calculator!$C$27)/1000)*(1+Calculator!$C$45+Calculator!$C$37)*Calculator!$C$39*(1-(1-MIN(Calculator!$C$44,MIN(1,E41+Calculator!$E$6/10*Constants!$B$16+Calculator!$C$36+Calculator!$C$40+Constants!$B$24*Calculator!$C$27)))*Constants!$B$6) -> 15.33264
A42: Cerulean Thread | B42: Dagger | C42: LHT 85 · Power 10 | D42: 14.5 | E42: 0.25 | F42: LHT | G42: 7.5 | I42: 0 | K42: 0 | L42: =D42*(1+0.75*(IFERROR(G42*INDEX(Calculator!$E$6:$E$23,MATCH(F42,Calculator!$A$6:$A$23,0)),0)+IFERROR(I42*INDEX(Calculator!$E$6:$E$23,MATCH(H42,Calculator!$A$6:$A$23,0)),0)+IFERROR(K42*INDEX(Calculator!$E$6:$E$23,MATCH(J42,Calculator!$A$6:$A$23,0)),0))*(1+Constants!$B$23*Calculator!$C$27)/1000)*(1+Calculator!$C$45+Calculator!$C$37)*Calculator!$C$39*(1-(1-MIN(Calculator!$C$44,MIN(1,E42+Calculator!$E$6/10*Constants!$B$16+Calculator!$C$36+Calculator!$C$40+Constants!$B$24*Calculator!$C$27)))*Constants!$B$6) -> 15.004455
A43: Champion's Dagger | B43: Dagger | C43: LHT 50 | D43: 16 | E43: 0 | F43: LHT | G43: 8 | I43: 0 | K43: 0 | L43: =D43*(1+0.75*(IFERROR(G43*INDEX(Calculator!$E$6:$E$23,MATCH(F43,Calculator!$A$6:$A$23,0)),0)+IFERROR(I43*INDEX(Calculator!$E$6:$E$23,MATCH(H43,Calculator!$A$6:$A$23,0)),0)+IFERROR(K43*INDEX(Calculator!$E$6:$E$23,MATCH(J43,Calculator!$A$6:$A$23,0)),0))*(1+Constants!$B$23*Calculator!$C$27)/1000)*(1+Calculator!$C$45+Calculator!$C$37)*Calculator!$C$39*(1-(1-MIN(Calculator!$C$44,MIN(1,E43+Calculator!$E$6/10*Constants!$B$16+Calculator!$C$36+Calculator!$C$40+Constants!$B$24*Calculator!$C$27)))*Constants!$B$6) -> 15.02664
A44: Champion's Sword | B44: Sword | C44: MED 40 | D44: 19 | E44: 0 | F44: MED | G44: 6.5 | I44: 0 | K44: 0 | L44: =D44*(1+0.75*(IFERROR(G44*INDEX(Calculator!$E$6:$E$23,MATCH(F44,Calculator!$A$6:$A$23,0)),0)+IFERROR(I44*INDEX(Calculator!$E$6:$E$23,MATCH(H44,Calculator!$A$6:$A$23,0)),0)+IFERROR(K44*INDEX(Calculator!$E$6:$E$23,MATCH(J44,Calculator!$A$6:$A$23,0)),0))*(1+Constants!$B$23*Calculator!$C$27)/1000)*(1+Calculator!$C$45+Calculator!$C$37)*Calculator!$C$39*(1-(1-MIN(Calculator!$C$44,MIN(1,E44+Calculator!$E$6/10*Constants!$B$16+Calculator!$C$36+Calculator!$C$40+Constants!$B$24*Calculator!$C$27)))*Constants!$B$6) -> 27.928034
A45: Chorus of Agonies | B45: Greataxe | C45: HVY 100 · STR 20 · Power 10 | D45: 26 | E45: 0 | F45: HVY | G45: 11 | I45: 0 | K45: 0 | L45: =D45*(1+0.75*(IFERROR(G45*INDEX(Calculator!$E$6:$E$23,MATCH(F45,Calculator!$A$6:$A$23,0)),0)+IFERROR(I45*INDEX(Calculator!$E$6:$E$23,MATCH(H45,Calculator!$A$6:$A$23,0)),0)+IFERROR(K45*INDEX(Calculator!$E$6:$E$23,MATCH(J45,Calculator!$A$6:$A$23,0)),0))*(1+Constants!$B$23*Calculator!$C$27)/1000)*(1+Calculator!$C$45+Calculator!$C$37)*Calculator!$C$39*(1-(1-MIN(Calculator!$C$44,MIN(1,E45+Calculator!$E$6/10*Constants!$B$16+Calculator!$C$36+Calculator!$C$40+Constants!$B$24*Calculator!$C$27)))*Constants!$B$6) -> 24.41829
A46: Coldpoint | B46: Rapier | C46: LHT 70 · ICE 25 | D46: 15 | E46: 0.1 | F46: LHT | G46: 7 | H46: ICE | I46: 4 | K46: 0 | L46: =D46*(1+0.75*(IFERROR(G46*INDEX(Calculator!$E$6:$E$23,MATCH(F46,Calculator!$A$6:$A$23,0)),0)+IFERROR(I46*INDEX(Calculator!$E$6:$E$23,MATCH(H46,Calculator!$A$6:$A$23,0)),0)+IFERROR(K46*INDEX(Calculator!$E$6:$E$23,MATCH(J46,Calculator!$A$6:$A$23,0)),0))*(1+Constants!$B$23*Calculator!$C$27)/1000)*(1+Calculator!$C$45+Calculator!$C$37)*Calculator!$C$39*(1-(1-MIN(Calculator!$C$44,MIN(1,E46+Calculator!$E$6/10*Constants!$B$16+Calculator!$C$36+Calculator!$C$40+Constants!$B$24*Calculator!$C$27)))*Constants!$B$6) -> 14.661225
A47: Coral Cestus | B47: Fist | C47: LHT 50 | D47: 14 | E47: 0.1 | F47: LHT | G47: 9.5 | I47: 0 | K47: 0 | L47: =D47*(1+0.75*(IFERROR(G47*INDEX(Calculator!$E$6:$E$23,MATCH(F47,Calculator!$A$6:$A$23,0)),0)+IFERROR(I47*INDEX(Calculator!$E$6:$E$23,MATCH(H47,Calculator!$A$6:$A$23,0)),0)+IFERROR(K47*INDEX(Calculator!$E$6:$E$23,MATCH(J47,Calculator!$A$6:$A$23,0)),0))*(1+Constants!$B$23*Calculator!$C$27)/1000)*(1+Calculator!$C$45+Calculator!$C$37)*Calculator!$C$39*(1-(1-MIN(Calculator!$C$44,MIN(1,E47+Calculator!$E$6/10*Constants!$B$16+Calculator!$C$36+Calculator!$C$40+Constants!$B$24*Calculator!$C$27)))*Constants!$B$6) -> 13.68381
A48: Crescendo | B48: Twinblade | C48: MED 75 | D48: 22 | E48: 0.05 | F48: MED | G48: 6 | I48: 0 | K48: 0 | L48: =D48*(1+0.75*(IFERROR(G48*INDEX(Calculator!$E$6:$E$23,MATCH(F48,Calculator!$A$6:$A$23,0)),0)+IFERROR(I48*INDEX(Calculator!$E$6:$E$23,MATCH(H48,Calculator!$A$6:$A$23,0)),0)+IFERROR(K48*INDEX(Calculator!$E$6:$E$23,MATCH(J48,Calculator!$A$6:$A$23,0)),0))*(1+Constants!$B$23*Calculator!$C$27)/1000)*(1+Calculator!$C$45+Calculator!$C$37)*Calculator!$C$39*(1-(1-MIN(Calculator!$C$44,MIN(1,E48+Calculator!$E$6/10*Constants!$B$16+Calculator!$C$36+Calculator!$C$40+Constants!$B$24*Calculator!$C$27)))*Constants!$B$6) -> 32.079793
A49: Crescent Cleaver | B49: Greatsword | C49: HVY 45 · STR 10 | D49: 22 | E49: 0 | F49: HVY | G49: 8 | I49: 0 | K49: 0 | L49: =D49*(1+0.75*(IFERROR(G49*INDEX(Calculator!$E$6:$E$23,MATCH(F49,Calculator!$A$6:$A$23,0)),0)+IFERROR(I49*INDEX(Calculator!$E$6:$E$23,MATCH(H49,Calculator!$A$6:$A$23,0)),0)+IFERROR(K49*INDEX(Calculator!$E$6:$E$23,MATCH(J49,Calculator!$A$6:$A$23,0)),0))*(1+Constants!$B$23*Calculator!$C$27)/1000)*(1+Calculator!$C$45+Calculator!$C$37)*Calculator!$C$39*(1-(1-MIN(Calculator!$C$44,MIN(1,E49+Calculator!$E$6/10*Constants!$B$16+Calculator!$C$36+Calculator!$C$40+Constants!$B$24*Calculator!$C$27)))*Constants!$B$6) -> 20.66163
A50: Crucible Rapier | B50: Rapier | C50: LHT 75 | D50: 15 | E50: 0.2 | F50: LHT | G50: 8 | I50: 0 | K50: 0 | L50: =D50*(1+0.75*(IFERROR(G50*INDEX(Calculator!$E$6:$E$23,MATCH(F50,Calculator!$A$6:$A$23,0)),0)+IFERROR(I50*INDEX(Calculator!$E$6:$E$23,MATCH(H50,Calculator!$A$6:$A$23,0)),0)+IFERROR(K50*INDEX(Calculator!$E$6:$E$23,MATCH(J50,Calculator!$A$6:$A$23,0)),0))*(1+Constants!$B$23*Calculator!$C$27)/1000)*(1+Calculator!$C$45+Calculator!$C$37)*Calculator!$C$39*(1-(1-MIN(Calculator!$C$44,MIN(1,E50+Calculator!$E$6/10*Constants!$B$16+Calculator!$C$36+Calculator!$C$40+Constants!$B$24*Calculator!$C$27)))*Constants!$B$6) -> 15.234975
A51: Crypt Blade | B51: Greatsword | C51: HVY 40 · SDW 75 · Power 10 | D51: 22 | E51: 0 | F51: HVY | G51: 4 | H51: SDW | I51: 9 | K51: 0 | L51: =D51*(1+0.75*(IFERROR(G51*INDEX(Calculator!$E$6:$E$23,MATCH(F51,Calculator!$A$6:$A$23,0)),0)+IFERROR(I51*INDEX(Calculator!$E$6:$E$23,MATCH(H51,Calculator!$A$6:$A$23,0)),0)+IFERROR(K51*INDEX(Calculator!$E$6:$E$23,MATCH(J51,Calculator!$A$6:$A$23,0)),0))*(1+Constants!$B$23*Calculator!$C$27)/1000)*(1+Calculator!$C$45+Calculator!$C$37)*Calculator!$C$39*(1-(1-MIN(Calculator!$C$44,MIN(1,E51+Calculator!$E$6/10*Constants!$B$16+Calculator!$C$36+Calculator!$C$40+Constants!$B$24*Calculator!$C$27)))*Constants!$B$6) -> 20.66163
A52: Curved Blade of Winds | B52: Sword | C52: MED 40 · WND 75 · Power 10 | D52: 17.5 | E52: 0.15 | F52: MED | G52: 5 | H52: WND | I52: 5 | K52: 0 | L52: =D52*(1+0.75*(IFERROR(G52*INDEX(Calculator!$E$6:$E$23,MATCH(F52,Calculator!$A$6:$A$23,0)),0)+IFERROR(I52*INDEX(Calculator!$E$6:$E$23,MATCH(H52,Calculator!$A$6:$A$23,0)),0)+IFERROR(K52*INDEX(Calculator!$E$6:$E$23,MATCH(J52,Calculator!$A$6:$A$23,0)),0))*(1+Constants!$B$23*Calculator!$C$27)/1000)*(1+Calculator!$C$45+Calculator!$C$37)*Calculator!$C$39*(1-(1-MIN(Calculator!$C$44,MIN(1,E52+Calculator!$E$6/10*Constants!$B$16+Calculator!$C$36+Calculator!$C$40+Constants!$B$24*Calculator!$C$27)))*Constants!$B$6) -> 25.020379
A53: Darkalloy Greatsword | B53: Greatsword | C53: HVY 75 · STR 10 | D53: 26 | E53: 0.1 | F53: HVY | G53: 8 | I53: 0 | K53: 0 | L53: =D53*(1+0.75*(IFERROR(G53*INDEX(Calculator!$E$6:$E$23,MATCH(F53,Calculator!$A$6:$A$23,0)),0)+IFERROR(I53*INDEX(Calculator!$E$6:$E$23,MATCH(H53,Calculator!$A$6:$A$23,0)),0)+IFERROR(K53*INDEX(Calculator!$E$6:$E$23,MATCH(J53,Calculator!$A$6:$A$23,0)),0))*(1+Constants!$B$23*Calculator!$C$27)/1000)*(1+Calculator!$C$45+Calculator!$C$37)*Calculator!$C$39*(1-(1-MIN(Calculator!$C$44,MIN(1,E53+Calculator!$E$6/10*Constants!$B$16+Calculator!$C$36+Calculator!$C$40+Constants!$B$24*Calculator!$C$27)))*Constants!$B$6) -> 25.41279
